Workbook

Sheet hr_last
A1: employee_id | B1: month | C1: full_name | D1: dept_l1 | E1: dept_l2 | F1: dept_l3 | G1: prof_group | H1: role | I1: grade | J1: rate | K1: salary | L1: hire_date | M1: manager_id
A2: 1000 | B2: 45809 | C2: Дмитрий Кузнецов | D2: Технологический блок | E2: Разработка | F2: Бэкенд | G2: Разработка | H2: Младший специалист | I2: 13 | J2: 0.5 | K2: 82500 | L2: 45342
A3: 1001 | B3: 45809 | C3: Анна Козлова | D3: Технологический блок | E3: Разработка | F3: Бэкенд | G3: Разработка | H3: Младший специалист | I3: 13 | J3: 1 | K3: 165000 | L3: 45342
A4: 1002 | B4: 45809 | C4: Иван Лебедев | D4: Технологический блок | E4: Разраб. | F4: Фронтенд | G4: Разработка | H4: Специалист | I4: 14 | J4: 1 | K4: 207000 | L4: 45342
A5: 1003 | B5: 45809 | C5: Ксения Попова | D5: Технологический блок | E5: Разработка | F5: Фронтенд | G5: Разработка | H5: Специалист | I5: 14 | J5: 1 | K5: 174000 | L5: 44256
A6: 1004 | B6: 45809 | C6: Роман Иванов | D6: Технологический блок | E6: Разработка | F6: Фронтенд | G6: Разработка | H6: Специалист | I6: 16 | J6: 1 | K6: 209000 | L6: 45601
A7: 1005 | B7: 45809 | C7: Татьяна Козлова | D7: Технологический блок | E7: Разработка | F7: Фронтенд | G7: Разработка | H7: Старший специалист | I7: 15 | J7: 1 | K7: 188000 | L7: 44256
A8: 1006 | B8: 45809 | C8: Алексей Новиков | D8: Технологический блок | E8: Разработка | F8: Бэкенд | G8: Разработка | H8: Старший специалист | I8: 15 | J8: 1 | K8: 216000 | L8: 44256
A9: 1007 | B9: 45809 | C9: Юлия Васильева | D9: Технологический блок | E9: разработка | F9: Фронтенд | G9: Разработка | H9: Ведущий специалист | I9: 16 | J9: 1 | K9: 231000 | L9: 45170
A10: 1008 | B10: 45809 | C10: Алексей Лебедев | D10: Технологический блок | E10: разработка | F10: Бэкенд | G10: Разработка | H10: Ведущий специалист | I10: 16 | J10: 1 | K10: 222000 | L10: 44727
A11: 1009 | B11: 45809 | C11: Ирина Соловьёва | D11: Технологический блок | E11: Разраб. | F11: Бэкенд | G11: Разработка | H11: Ведущий специалист | I11: 16 | J11: 1 | K11: 195000 | L11: 43845
A12: 1010 | B12: 45809 | C12: Алексей Козлов | D12: Технологический блок | E12: Разраб. | F12: Бэкенд | G12: Разработка | H12: Ведущий специалист | I12: 16 | J12: 0.6 | K12: 121800 | L12: 45170
A13: 1011 | B13: 45809 | C13: Маргарита Соколова | D13: Технологический блок | E13: разработка | F13: Фронтенд | G13: Разработка | H13: Руководитель группы | I13: 17 | J13: 1 | K13: 247000 | L13: 44936
... A17: 1015 | B17: 45809 | C17: Светлана Смирнова | D17: Технологический блок | E17: Разработка | F17: Фронтенд | G17: Разработка | H17: Руководитель отдела | I17: 18 | J17: 1 | K17: 228000 | L17: 44256
A18: 1016 | B18: 45809 | C18: Григорий Смирнов | D18: Технологический блок | E18: Аналитика данных | G18: Аналитика данных | H18: Младший специалист | I18: 13 | J18: 1 | K18: 163000 | L18: 44936
A19: 1017 | B19: 45809 | C19: Полина Козлова | D19: Технологический блок | E19: аналитика данных | G19: Аналитика данных | H19: Младший специалист | I19: 13 | J19: 1 | K19: 146000 | L19: 44520
A20: 1018 | B20: 45809 | C20: Иван Соловьёв | D20: Технологический блок | E20: аналитика данных | G20: Аналитика данных | H20: Младший специалист | I20: 13 | J20: 0.8 | K20: 151200 | L20: 45601
A21: 1019 | B21: 45809 | C21: Ирина Кузнецова | D21: Технологический блок | E21: Аналитика данных | G21: Аналитика данных | H21: Специалист | I21: 14 | J21: 0.6 | K21: 96600 | L21: 44256
A22: 1020 | B22: 45809 | C22: Сергей Голубев | D22: Технологический блок | E22: Аналитика данных | G22: Аналитика данных | H22: Специалист | I22: 14 | J22: 0.8 | K22: 151200 | L22: 44520
A23: 1021 | B23: 45809 | C23: Дарья Волкова | D23: Технологический блок | E23: Аналитика данных | G23: Аналитика данных | H23: Старший специалист | I23: 15 | J23: 0.8 | K23: 158400 | L23: 45342
A24: 1022 | B24: 45809 | C24: Дмитрий Новиков | D24: Технологический блок | E24: аналитика данных | G24: Аналитика данных | H24: Старший специалист | I24: 15 | J24: 1 | K24: 185000 | L24: 44727
A25: 1023 | B25: 45809 | C25: Ирина Новикова | D25: Технологический блок | E25: Аналитика данных | G25: Аналитика данных | H25: Старший специалист | I25: 15 | J25: 1 | K25: 189000 | L25: 43845
A26: 1024 | B26: 45809 | C26: Артём Кузнецов | D26: Технологический блок | E26: аналитика данных | G26: Аналитика данных | H26: Ведущий специалист | I26: 16 | J26: 1 | K26: 217000 | L26: 44727
A27: 1025 | B27: 45809 | C27: Наталья Голубева | D27: Технологический блок | E27: аналитика данных | G27: Аналитика данных | H27: Ведущий специалист | I27: 16 | J27: 1 | K27: 176000 | L27: 44727
A28: 1026 | B28: 45809 | C28: Денис Васильев | D28: Технологический блок | E28: аналитика данных | G28: Аналитика данных | H28: Руководитель группы | I28: 17 | J28: 1 | K28: 178000 | L28: 45342
A29: 1027 | B29: 45809 | C29: Елена Иванова | D29: Технологический блок | E29: аналитика данных | G29: Аналитика данных | H29: Руководитель группы | I29: 17 | J29: 1 | K29: 216000 | L29: 45342
... A104: 1102 | B104: 45809 | C104: Роман Кузнецов | D104: Операционный блок | E104: Поддержка | G104: Поддержка | H104: Старший специалист | I104: 15 | J104: 0.5 | K104: 66500 | L104: 44520
A105: 1103 | B105: 45809 | C105: Станислав Ершов | D105: Технологический блок | E105: Разраб. | F105: Бэкенд | G105: Разработка | H105: Старший специалист | I105: 15 | J105: 1 | K105: 132000 | L105: 44621
A106: 1104 | B106: 45809 | C106: Регина Панкратова | D106: Технологический блок | E106: аналитика данных | G106: Аналитика данных | H106: Старший специалист | I106: 15 | J106: 1 | K106: 121000 | L106: 44621
A107: 1105 | B107: 45809 | C107: Матвей Крылов | D107: Технологический блок | E107: Инфраструктура | G107: Инфраструктура | H107: Старший специалист | I107: 15 | J107: 1 | K107: 123000 | L107: 44621
A108: 1106 | B108: 45809 | C108: Аркадий Логинов | D108: Финансовый блок | E108: Бюджетирование | G108: Бюджетирование | H108: Старший специалист | I108: 15 | J108: 1 | K108: 113000 | L108: 44621
A109: 1107 | B109: 45809 | C109: Жанна Егорова | D109: Финансовый блок | E109: Компенсации и льготы | G109: Компенсации и льготы | H109: Старший специалист | I109: 15 | J109: 1 | K109: 108000 | L109: 44621
A110: 1108 | B110: 45809 | C110: Валерия Носова | D110: Операционный блок | E110: HR | G110: HR | H110: Специалист | I110: 14 | J110: 1 | K110: 99000 | L110: 44621
A111: 1109 | B111: 45809 | C111: Тимофей Гущин | D111: Операционный блок | E111: Поддержка | G111: Поддержка | H111: Младший специалист | I111: 13 | J111: 1 | K111: 75000 | L111: 44621
A112: 1110 | B112: 45809 | C112: Эдуард Лаптев | D112: Технологический блок | E112: Аналитика данных | G112: Аналитика данных | H112: Старший специалист | I112: 15 | J112: 0.5 | K112: 64000 | L112: 45108
A113: 1111 | B113: 45809 | C113: Виктор Григорьев | D113: Технологический блок | E113: разработка | G113: Разработка | H113: Руководитель разработки | I113: 16 | J113: 1 | K113: 230000 | L113: 43586
A114: 1112 | B114: 45809 | C114: Павел Орлов | D114: Технологический блок | E114: разработка | F114: Бэкенд | G114: Разработка | H114: Руководитель разработки | I114: 16 | J114: 1 | K114: 210000 | L114: 44378
A115: 1113 | B115: 45809 | C115: Родион Зайцев | D115: Технологический блок | E115: Инфраструктура | G115: Инфраструктура | H115: Руководитель группы | I115: 17 | J115: 1 | K115: 194000 | L115: 44075
A116: 1114 | B116: 45809 | C116: Глеб Фомин | D116: Технологический блок | E116: Инфраструктура | G116: Инфраструктура | H116: Ведущий инженер | I116: 18 | J116: 1 | K116: 202000 | L116: 44562 | M116: 1113
A117: 1115 | B117: 45809 | C117: Марина Белова | D117: Финансовый блок | E117: Компенсации и льготы | G117: Компенсации и льготы | H117: Старший специалист | I117: 15 | J117: 1 | K117: 92000 | L117: 44652
...

Sheet salary_bands
A1: prof_group | B1: grade | C1: salary_min | D1: salary_mid | E1: salary_max
A2: Разработка | B2: 13 | C2: 153000 | D2: 180000 | E2: 207000
A3: Разработка | B3: 14 | C3: 162000 | D3: 190000 | E3: 218000
A4: Разработка | B4: 15 | C4: 170000 | D4: 200000 | E4: 230000
A5: Разработка | B5: 16 | C5: 178000 | D5: 210000 | E5: 241000
A6: Разработка | B6: 17 | C6: 187000 | D6: 220000 | E6: 253000
A7: Разработка | B7: 18 | C7: 196000 | D7: 230000 | E7: 264000
A8: Аналитика данных | B8: 13 | C8: 141000 | D8: 166000 | E8: 191000
A9: Аналитика данных | B9: 14 | C9: 149000 | D9: 175000 | E9: 201000
A10: Аналитика данных | B10: 15 | C10: 156000 | D10: 184000 | E10: 212000
A11: Аналитика данных | B11: 16 | C11: 164000 | D11: 193000 | E11: 222000
A12: Аналитика данных | B12: 17 | C12: 172000 | D12: 202000 | E12: 232000
A13: Инфраструктура | B13: 13 | C13: 134000 | D13: 158000 | E13: 182000
... A35: Поддержка | B35: 15 | C35: 109000 | D35: 128000 | E35: 147000

Sheet Анализ
A1: employee_id | B1: month | C1: full_name | D1: dept_l1 | E1: dept_l2 | F1: dept_l3 | G1: prof_group | H1: role | I1: grade | J1: rate | K1: salary | L1: hire_date | M1: manager_id | N1: salary_min | O1: salary_mid | P1: salary_max | Q1: статус_вилки | R1: разрыв_до_минимума | S1: полный_оклад | T1: разрыв_до_середины | U1: факт_прибавка_мин | V1: факт_прибавка_сер | W1: итого_прибавка
A2: 1000 | B2: 45809 | C2: Дмитрий Кузнецов | D2: Технологический блок | E2: Разработка | F2: Бэкенд | G2: Разработка | H2: Младший специалист | I2: 13 | J2: 0.5 | K2: 82500 | L2: 45342 | N2: =SUMIFS(salary_bands[salary_min],salary_bands[prof_group],G2,salary_bands[grade],I2) -> 153000 | O2: =SUMIFS(salary_bands[salary_mid],salary_bands[prof_group],G2,salary_bands[grade],I2) -> 180000 | P2: =SUMIFS(salary_bands[salary_max],salary_bands[prof_group],G2,salary_bands[grade],I2) -> 207000 | Q2: {=_xlfn.IFS(S2<N2,"ниже минимума",S2<=O2,"ниже середины",S2<=P2,"выше середины",S2>P2,"выше максимума")} -> ниже середины | R2: =IF(S2<N2,N2-S2,0) -> 0 | S2: =K2/J2 -> 165000 | T2: =IF(S2<O2,O2-S2,0) -> 15000 | U2: =IF(R2>0, R2*J2, 0) -> 0 | V2: =IF(AND(R2=0, T2>3000), T2*J2, 0) -> 7500 | W2: =U2+V2 -> 7500
A3: 1001 | B3: 45809 | C3: Анна Козлова | D3: Технологический блок | E3: Разработка | F3: Бэкенд | G3: Разработка | H3: Младший специалист | I3: 13 | J3: 1 | K3: 165000 | L3: 45342 | N3: =SUMIFS(salary_bands[salary_min],salary_bands[prof_group],G3,salary_bands[grade],I3) -> 153000 | O3: =SUMIFS(salary_bands[salary_mid],salary_bands[prof_group],G3,salary_bands[grade],I3) -> 180000 | P3: =SUMIFS(salary_bands[salary_max],salary_bands[prof_group],G3,salary_bands[grade],I3) -> 207000 | Q3: {=_xlfn.IFS(S3<N3,"ниже минимума",S3<=O3,"ниже середины",S3<=P3,"выше середины",S3>P3,"выше максимума")} -> ниже середины | R3: =IF(S3<N3,N3-S3,0) -> 0 | S3: =K3/J3 -> 165000 | T3: =IF(S3<O3,O3-S3,0) -> 15000 | U3: =IF(R3>0, R3*J3, 0) -> 0 | V3: =IF(AND(R3=0, T3>3000), T3*J3, 0) -> 15000 | W3: =U3+V3 -> 15000
A4: 1002 | B4: 45809 | C4: Иван Лебедев | D4: Технологический блок | E4: Разраб. | F4: Фронтенд | G4: Разработка | H4: Специалист | I4: 14 | J4: 1 | K4: 207000 | L4: 45342 | N4: =SUMIFS(salary_bands[salary_min],salary_bands[prof_group],G4,salary_bands[grade],I4) -> 162000 | O4: =SUMIFS(salary_bands[salary_mid],salary_bands[prof_group],G4,salary_bands[grade],I4) -> 190000 | P4: =SUMIFS(salary_bands[salary_max],salary_bands[prof_group],G4,salary_bands[grade],I4) -> 218000 | Q4: {=_xlfn.IFS(S4<N4,"ниже минимума",S4<=O4,"ниже середины",S4<=P4,"выше середины",S4>P4,"выше максимума")} -> выше середины | R4: =IF(S4<N4,N4-S4,0) -> 0 | S4: =K4/J4 -> 207000 | T4: =IF(S4<O4,O4-S4,0) -> 0 | U4: =IF(R4>0, R4*J4, 0) -> 0 | V4: =IF(AND(R4=0, T4>3000), T4*J4, 0) -> 0 | W4: =U4+V4 -> 0
A5: 1003 | B5: 45809 | C5: Ксения Попова | D5: Технологический блок | E5: Разработка | F5: Фронтенд | G5: Разработка | H5: Специалист | I5: 14 | J5: 1 | K5: 174000 | L5: 44256 | N5: =SUMIFS(salary_bands[salary_min],salary_bands[prof_group],G5,salary_bands[grade],I5) -> 162000 | O5: =SUMIFS(salary_bands[salary_mid],salary_bands[prof_group],G5,salary_bands[grade],I5) -> 190000 | P5: =SUMIFS(salary_bands[salary_max],salary_bands[prof_group],G5,salary_bands[grade],I5) -> 218000 | Q5: {=_xlfn.IFS(S5<N5,"ниже минимума",S5<=O5,"ниже середины",S5<=P5,"выше середины",S5>P5,"выше максимума")} -> ниже середины | R5: =IF(S5<N5,N5-S5,0) -> 0 | S5: =K5/J5 -> 174000 | T5: =IF(S5<O5,O5-S5,0) -> 16000 | U5: =IF(R5>0, R5*J5, 0) -> 0 | V5: =IF(AND(R5=0, T5>3000), T5*J5, 0) -> 16000 | W5: =U5+V5 -> 16000
A6: 1004 | B6: 45809 | C6: Роман Иванов | D6: Технологический блок | E6: Разработка | F6: Фронтенд | G6: Разработка | H6: Специалист | I6: 16 | J6: 1 | K6: 209000 | L6: 45601 | N6: =SUMIFS(salary_bands[salary_min],salary_bands[prof_group],G6,salary_bands[grade],I6) -> 178000 | O6: =SUMIFS(salary_bands[salary_mid],salary_bands[prof_group],G6,salary_bands[grade],I6) -> 210000 | P6: =SUMIFS(salary_bands[salary_max],salary_bands[prof_group],G6,salary_bands[grade],I6) -> 241000 | Q6: {=_xlfn.IFS(S6<N6,"ниже минимума",S6<=O6,"ниже середины",S6<=P6,"выше середины",S6>P6,"выше максимума")} -> ниже середины | R6: =IF(S6<N6,N6-S6,0) -> 0 | S6: =K6/J6 -> 209000 | T6: =IF(S6<O6,O6-S6,0) -> 1000 | U6: =IF(R6>0, R6*J6, 0) -> 0 | V6: =IF(AND(R6=0, T6>3000), T6*J6, 0) -> 0 | W6: =U6+V6 -> 0
A7: 1005 | B7: 45809 | C7: Татьяна Козлова | D7: Технологический блок | E7: Разработка | F7: Фронтенд | G7: Разработка | H7: Старший специалист | I7: 15 | J7: 1 | K7: 188000 | L7: 44256 | N7: =SUMIFS(salary_bands[salary_min],salary_bands[prof_group],G7,salary_bands[grade],I7) -> 170000 | O7: =SUMIFS(salary_bands[salary_mid],salary_bands[prof_group],G7,salary_bands[grade],I7) -> 200000 | P7: =SUMIFS(salary_bands[salary_max],salary_bands[prof_group],G7,salary_bands[grade],I7) -> 230000 | Q7: {=_xlfn.IFS(S7<N7,"ниже минимума",S7<=O7,"ниже середины",S7<=P7,"выше середины",S7>P7,"выше максимума")} -> ниже середины | R7: =IF(S7<N7,N7-S7,0) -> 0 | S7: =K7/J7 -> 188000 | T7: =IF(S7<O7,O7-S7,0) -> 12000 | U7: =IF(R7>0, R7*J7, 0) -> 0 | V7: =IF(AND(R7=0, T7>3000), T7*J7, 0) -> 12000 | W7: =U7+V7 -> 12000
A8: 1006 | B8: 45809 | C8: Алексей Новиков | D8: Технологический блок | E8: Разработка | F8: Бэкенд | G8: Разработка | H8: Старший специалист | I8: 15 | J8: 1 | K8: 216000 | L8: 44256 | N8: =SUMIFS(salary_bands[salary_min],salary_bands[prof_group],G8,salary_bands[grade],I8) -> 170000 | O8: =SUMIFS(salary_bands[salary_mid],salary_bands[prof_group],G8,salary_bands[grade],I8) -> 200000 | P8: =SUMIFS(salary_bands[salary_max],salary_bands[prof_group],G8,salary_bands[grade],I8) -> 230000 | Q8: {=_xlfn.IFS(S8<N8,"ниже минимума",S8<=O8,"ниже середины",S8<=P8,"выше середины",S8>P8,"выше максимума")} -> выше середины | R8: =IF(S8<N8,N8-S8,0) -> 0 | S8: =K8/J8 -> 216000 | T8: =IF(S8<O8,O8-S8,0) -> 0 | U8: =IF(R8>0, R8*J8, 0) -> 0 | V8: =IF(AND(R8=0, T8>3000), T8*J8, 0) -> 0 | W8: =U8+V8 -> 0
A9: 1007 | B9: 45809 | C9: Юлия Васильева | D9: Технологический блок | E9: разработка | F9: Фронтенд | G9: Разработка | H9: Ведущий специалист | I9: 16 | J9: 1 | K9: 231000 | L9: 45170 | N9: =SUMIFS(salary_bands[salary_min],salary_bands[prof_group],G9,salary_bands[grade],I9) -> 178000 | O9: =SUMIFS(salary_bands[salary_mid],salary_bands[prof_group],G9,salary_bands[grade],I9) -> 210000 | P9: =SUMIFS(salary_bands[salary_max],salary_bands[prof_group],G9,salary_bands[grade],I9) -> 241000 | Q9: {=_xlfn.IFS(S9<N9,"ниже минимума",S9<=O9,"ниже середины",S9<=P9,"выше середины",S9>P9,"выше максимума")} -> выше середины | R9: =IF(S9<N9,N9-S9,0) -> 0 | S9: =K9/J9 -> 231000 | T9: =IF(S9<O9,O9-S9,0) -> 0 | U9: =IF(R9>0, R9*J9, 0) -> 0 | V9: =IF(AND(R9=0, T9>3000), T9*J9, 0) -> 0 | W9: =U9+V9 -> 0
A10: 1008 | B10: 45809 | C10: Алексей Лебедев | D10: Технологический блок | E10: разработка | F10: Бэкенд | G10: Разработка | H10: Ведущий специалист | I10: 16 | J10: 1 | K10: 222000 | L10: 44727 | N10: =SUMIFS(salary_bands[salary_min],salary_bands[prof_group],G10,salary_bands[grade],I10) -> 178000 | O10: =SUMIFS(salary_bands[salary_mid],salary_bands[prof_group],G10,salary_bands[grade],I10) -> 210000 | P10: =SUMIFS(salary_bands[salary_max],salary_bands[prof_group],G10,salary_bands[grade],I10) -> 241000 | Q10: {=_xlfn.IFS(S10<N10,"ниже минимума",S10<=O10,"ниже середины",S10<=P10,"выше середины",S10>P10,"выше максимума")} -> выше середины | R10: =IF(S10<N10,N10-S10,0) -> 0 | S10: =K10/J10 -> 222000 | T10: =IF(S10<O10,O10-S10,0) -> 0 | U10: =IF(R10>0, R10*J10, 0) -> 0 | V10: =IF(AND(R10=0, T10>3000), T10*J10, 0) -> 0 | W10: =U10+V10 -> 0
A11: 1009 | B11: 45809 | C11: Ирина Соловьёва | D11: Технологический блок | E11: Разраб. | F11: Бэкенд | G11: Разработка | H11: Ведущий специалист | I11: 16 | J11: 1 | K11: 195000 | L11: 43845 | N11: =SUMIFS(salary_bands[salary_min],salary_bands[prof_group],G11,salary_bands[grade],I11) -> 178000 | O11: =SUMIFS(salary_bands[salary_mid],salary_bands[prof_group],G11,salary_bands[grade],I11) -> 210000 | P11: =SUMIFS(salary_bands[salary_max],salary_bands[prof_group],G11,salary_bands[grade],I11) -> 241000 | Q11: {=_xlfn.IFS(S11<N11,"ниже минимума",S11<=O11,"ниже середины",S11<=P11,"выше середины",S11>P11,"выше максимума")} -> ниже середины | R11: =IF(S11<N11,N11-S11,0) -> 0 | S11: =K11/J11 -> 195000 | T11: =IF(S11<O11,O11-S11,0) -> 15000 | U11: =IF(R11>0, R11*J11, 0) -> 0 | V11: =IF(AND(R11=0, T11>3000), T11*J11, 0) -> 15000 | W11: =U11+V11 -> 15000
A12: 1010 | B12: 45809 | C12: Алексей Козлов | D12: Технологический блок | E12: Разраб. | F12: Бэкенд | G12: Разработка | H12: Ведущий специалист | I12: 16 | J12: 0.6 | K12: 121800 | L12: 45170 | N12: =SUMIFS(salary_bands[salary_min],salary_bands[prof_group],G12,salary_bands[grade],I12) -> 178000 | O12: =SUMIFS(salary_bands[salary_mid],salary_bands[prof_group],G12,salary_bands[grade],I12) -> 210000 | P12: =SUMIFS(salary_bands[salary_max],salary_bands[prof_group],G12,salary_bands[grade],I12) -> 241000 | Q12: {=_xlfn.IFS(S12<N12,"ниже минимума",S12<=O12,"ниже середины",S12<=P12,"выше середины",S12>P12,"выше максимума")} -> ниже середины | R12: =IF(S12<N12,N12-S12,0) -> 0 | S12: =K12/J12 -> 203000 | T12: =IF(S12<O12,O12-S12,0) -> 7000 | U12: =IF(R12>0, R12*J12, 0) -> 0 | V12: =IF(AND(R12=0, T12>3000), T12*J12, 0) -> 4200 | W12: =U12+V12 -> 4200
A13: 1011 | B13: 45809 | C13: Маргарита Соколова | D13: Технологический блок | E13: разработка | F13: Фронтенд | G13: Разработка | H13: Руководитель группы | I13: 17 | J13: 1 | K13: 247000 | L13: 44936 | N13: =SUMIFS(salary_bands[salary_min],salary_bands[prof_group],G13,salary_bands[grade],I13) -> 187000 | O13: =SUMIFS(salary_bands[salary_mid],salary_bands[prof_group],G13,salary_bands[grade],I13) -> 220000 | P13: =SUMIFS(salary_bands[salary_max],salary_bands[prof_group],G13,salary_bands[grade],I13) -> 253000 | Q13: {=_xlfn.IFS(S13<N13,"ниже минимума",S13<=O13,"ниже середины",S13<=P13,"выше середины",S13>P13,"выше максимума")} -> выше середины | R13: =IF(S13<N13,N13-S13,0) -> 0 | S13: =K13/J13 -> 247000 | T13: =IF(S13<O13,O13-S13,0) -> 0 | U13: =IF(R13>0, R13*J13, 0) -> 0 | V13: =IF(AND(R13=0, T13>3000), T13*J13, 0) -> 0 | W13: =U13+V13 -> 0
... A17: 1015 | B17: 45809 | C17: Светлана Смирнова | D17: Технологический блок | E17: Разработка | F17: Фронтенд | G17: Разработка | H17: Руководитель отдела | I17: 18 | J17: 1 | K17: 228000 | L17: 44256 | N17: =SUMIFS(salary_bands[salary_min],salary_bands[prof_group],G17,salary_bands[grade],I17) -> 196000 | O17: =SUMIFS(salary_bands[salary_mid],salary_bands[prof_group],G17,salary_bands[grade],I17) -> 230000 | P17: =SUMIFS(salary_bands[salary_max],salary_bands[prof_group],G17,salary_bands[grade],I17) -> 264000 | Q17: {=_xlfn.IFS(S17<N17,"ниже минимума",S17<=O17,"ниже середины",S17<=P17,"выше середины",S17>P17,"выше максимума")} -> ниже середины | R17: =IF(S17<N17,N17-S17,0) -> 0 | S17: =K17/J17 -> 228000 | T17: =IF(S17<O17,O17-S17,0) -> 2000 | U17: =IF(R17>0, R17*J17, 0) -> 0 | V17: =IF(AND(R17=0, T17>3000), T17*J17, 0) -> 0 | W17: =U17+V17 -> 0
A18: 1016 | B18: 45809 | C18: Григорий Смирнов | D18: Технологический блок | E18: Аналитика данных | G18: Аналитика данных | H18: Младший специалист | I18: 13 | J18: 1 | K18: 163000 | L18: 44936 | N18: =SUMIFS(salary_bands[salary_min],salary_bands[prof_group],G18,salary_bands[grade],I18) -> 141000 | O18: =SUMIFS(salary_bands[salary_mid],salary_bands[prof_group],G18,salary_bands[grade],I18) -> 166000 | P18: =SUMIFS(salary_bands[salary_max],salary_bands[prof_group],G18,salary_bands[grade],I18) -> 191000 | Q18: {=_xlfn.IFS(S18<N18,"ниже минимума",S18<=O18,"ниже середины",S18<=P18,"выше середины",S18>P18,"выше максимума")} -> ниже середины | R18: =IF(S18<N18,N18-S18,0) -> 0 | S18: =K18/J18 -> 163000 | T18: =IF(S18<O18,O18-S18,0) -> 3000 | U18: =IF(R18>0, R18*J18, 0) -> 0 | V18: =IF(AND(R18=0, T18>3000), T18*J18, 0) -> 0 | W18: =U18+V18 -> 0
A19: 1017 | B19: 45809 | C19: Полина Козлова | D19: Технологический блок | E19: аналитика данных | G19: Аналитика данных | H19: Младший специалист | I19: 13 | J19: 1 | K19: 146000 | L19: 44520 | N19: =SUMIFS(salary_bands[salary_min],salary_bands[prof_group],G19,salary_bands[grade],I19) -> 141000 | O19: =SUMIFS(salary_bands[salary_mid],salary_bands[prof_group],G19,salary_bands[grade],I19) -> 166000 | P19: =SUMIFS(salary_bands[salary_max],salary_bands[prof_group],G19,salary_bands[grade],I19) -> 191000 | Q19: {=_xlfn.IFS(S19<N19,"ниже минимума",S19<=O19,"ниже середины",S19<=P19,"выше середины",S19>P19,"выше максимума")} -> ниже середины | R19: =IF(S19<N19,N19-S19,0) -> 0 | S19: =K19/J19 -> 146000 | T19: =IF(S19<O19,O19-S19,0) -> 20000 | U19: =IF(R19>0, R19*J19, 0) -> 0 | V19: =IF(AND(R19=0, T19>3000), T19*J19, 0) -> 20000 | W19: =U19+V19 -> 20000
A20: 1018 | B20: 45809 | C20: Иван Соловьёв | D20: Технологический блок | E20: аналитика данных | G20: Аналитика данных | H20: Младший специалист | I20: 13 | J20: 0.8 | K20: 151200 | L20: 45601 | N20: =SUMIFS(salary_bands[salary_min],salary_bands[prof_group],G20,salary_bands[grade],I20) -> 141000 | O20: =SUMIFS(salary_bands[salary_mid],salary_bands[prof_group],G20,salary_bands[grade],I20) -> 166000 | P20: =SUMIFS(salary_bands[salary_max],salary_bands[prof_group],G20,salary_bands[grade],I20) -> 191000 | Q20: {=_xlfn.IFS(S20<N20,"ниже минимума",S20<=O20,"ниже середины",S20<=P20,"выше середины",S20>P20,"выше максимума")} -> выше середины | R20: =IF(S20<N20,N20-S20,0) -> 0 | S20: =K20/J20 -> 189000 | T20: =IF(S20<O20,O20-S20,0) -> 0 | U20: =IF(R20>0, R20*J20, 0) -> 0 | V20: =IF(AND(R20=0, T20>3000), T20*J20, 0) -> 0 | W20: =U20+V20 -> 0
A21: 1019 | B21: 45809 | C21: Ирина Кузнецова | D21: Технологический блок | E21: Аналитика данных | G21: Аналитика данных | H21: Специалист | I21: 14 | J21: 0.6 | K21: 96600 | L21: 44256 | N21: =SUMIFS(salary_bands[salary_min],salary_bands[prof_group],G21,salary_bands[grade],I21) -> 149000 | O21: =SUMIFS(salary_bands[salary_mid],salary_bands[prof_group],G21,salary_bands[grade],I21) -> 175000 | P21: =SUMIFS(salary_bands[salary_max],salary_bands[prof_group],G21,salary_bands[grade],I21) -> 201000 | Q21: {=_xlfn.IFS(S21<N21,"ниже минимума",S21<=O21,"ниже середины",S21<=P21,"выше середины",S21>P21,"выше максимума")} -> ниже середины | R21: =IF(S21<N21,N21-S21,0) -> 0 | S21: =K21/J21 -> 161000 | T21: =IF(S21<O21,O21-S21,0) -> 14000 | U21: =IF(R21>0, R21*J21, 0) -> 0 | V21: =IF(AND(R21=0, T21>3000), T21*J21, 0) -> 8400 | W21: =U21+V21 -> 8400
A22: 1020 | B22: 45809 | C22: Сергей Голубев | D22: Технологический блок | E22: Аналитика данных | G22: Аналитика данных | H22: Специалист | I22: 14 | J22: 0.8 | K22: 151200 | L22: 44520 | N22: =SUMIFS(salary_bands[salary_min],salary_bands[prof_group],G22,salary_bands[grade],I22) -> 149000 | O22: =SUMIFS(salary_bands[salary_mid],salary_bands[prof_group],G22,salary_bands[grade],I22) -> 175000 | P22: =SUMIFS(salary_bands[salary_max],salary_bands[prof_group],G22,salary_bands[grade],I22) -> 201000 | Q22: {=_xlfn.IFS(S22<N22,"ниже минимума",S22<=O22,"ниже середины",S22<=P22,"выше середины",S22>P22,"выше максимума")} -> выше середины | R22: =IF(S22<N22,N22-S22,0) -> 0 | S22: =K22/J22 -> 189000 | T22: =IF(S22<O22,O22-S22,0) -> 0 | U22: =IF(R22>0, R22*J22, 0) -> 0 | V22: =IF(AND(R22=0, T22>3000), T22*J22, 0) -> 0 | W22: =U22+V22 -> 0
A23: 1021 | B23: 45809 | C23: Дарья Волкова | D23: Технологический блок | E23: Аналитика данных | G23: Аналитика данных | H23: Старший специалист | I23: 15 | J23: 0.8 | K23: 158400 | L23: 45342 | N23: =SUMIFS(salary_bands[salary_min],salary_bands[prof_group],G23,salary_bands[grade],I23) -> 156000 | O23: =SUMIFS(salary_bands[salary_mid],salary_bands[prof_group],G23,salary_bands[grade],I23) -> 184000 | P23: =SUMIFS(salary_bands[salary_max],salary_bands[prof_group],G23,salary_bands[grade],I23) -> 212000 | Q23: {=_xlfn.IFS(S23<N23,"ниже минимума",S23<=O23,"ниже середины",S23<=P23,"выше середины",S23>P23,"выше максимума")} -> выше середины | R23: =IF(S23<N23,N23-S23,0) -> 0 | S23: =K23/J23 -> 198000 | T23: =IF(S23<O23,O23-S23,0) -> 0 | U23: =IF(R23>0, R23*J23, 0) -> 0 | V23: =IF(AND(R23=0, T23>3000), T23*J23, 0) -> 0 | W23: =U23+V23 -> 0
A24: 1022 | B24: 45809 | C24: Дмитрий Новиков | D24: Технологический блок | E24: аналитика данных | G24: Аналитика данных | H24: Старший специалист | I24: 15 | J24: 1 | K24: 185000 | L24: 44727 | N24: =SUMIFS(salary_bands[salary_min],salary_bands[prof_group],G24,salary_bands[grade],I24) -> 156000 | O24: =SUMIFS(salary_bands[salary_mid],salary_bands[prof_group],G24,salary_bands[grade],I24) -> 184000 | P24: =SUMIFS(salary_bands[salary_max],salary_bands[prof_group],G24,salary_bands[grade],I24) -> 212000 | Q24: {=_xlfn.IFS(S24<N24,"ниже минимума",S24<=O24,"ниже середины",S24<=P24,"выше середины",S24>P24,"выше максимума")} -> выше середины | R24: =IF(S24<N24,N24-S24,0) -> 0 | S24: =K24/J24 -> 185000 | T24: =IF(S24<O24,O24-S24,0) -> 0 | U24: =IF(R24>0, R24*J24, 0) -> 0 | V24: =IF(AND(R24=0, T24>3000), T24*J24, 0) -> 0 | W24: =U24+V24 -> 0
A25: 1023 | B25: 45809 | C25: Ирина Новикова | D25: Технологический блок | E25: Аналитика данных | G25: Аналитика данных | H25: Старший специалист | I25: 15 | J25: 1 | K25: 189000 | L25: 43845 | N25: =SUMIFS(salary_bands[salary_min],salary_bands[prof_group],G25,salary_bands[grade],I25) -> 156000 | O25: =SUMIFS(salary_bands[salary_mid],salary_bands[prof_group],G25,salary_bands[grade],I25) -> 184000 | P25: =SUMIFS(salary_bands[salary_max],salary_bands[prof_group],G25,salary_bands[grade],I25) -> 212000 | Q25: {=_xlfn.IFS(S25<N25,"ниже минимума",S25<=O25,"ниже середины",S25<=P25,"выше середины",S25>P25,"выше максимума")} -> выше середины | R25: =IF(S25<N25,N25-S25,0) -> 0 | S25: =K25/J25 -> 189000 | T25: =IF(S25<O25,O25-S25,0) -> 0 | U25: =IF(R25>0, R25*J25, 0) -> 0 | V25: =IF(AND(R25=0, T25>3000), T25*J25, 0) -> 0 | W25: =U25+V25 -> 0
A26: 1024 | B26: 45809 | C26: Артём Кузнецов | D26: Технологический блок | E26: аналитика данных | G26: Аналитика данных | H26: Ведущий специалист | I26: 16 | J26: 1 | K26: 217000 | L26: 44727 | N26: =SUMIFS(salary_bands[salary_min],salary_bands[prof_group],G26,salary_bands[grade],I26) -> 164000 | O26: =SUMIFS(salary_bands[salary_mid],salary_bands[prof_group],G26,salary_bands[grade],I26) -> 193000 | P26: =SUMIFS(salary_bands[salary_max],salary_bands[prof_group],G26,salary_bands[grade],I26) -> 222000 | Q26: {=_xlfn.IFS(S26<N26,"ниже минимума",S26<=O26,"ниже середины",S26<=P26,"выше середины",S26>P26,"выше максимума")} -> выше середины | R26: =IF(S26<N26,N26-S26,0) -> 0 | S26: =K26/J26 -> 217000 | T26: =IF(S26<O26,O26-S26,0) -> 0 | U26: =IF(R26>0, R26*J26, 0) -> 0 | V26: =IF(AND(R26=0, T26>3000), T26*J26, 0) -> 0 | W26: =U26+V26 -> 0
A27: 1025 | B27: 45809 | C27: Наталья Голубева | D27: Технологический блок | E27: аналитика данных | G27: Аналитика данных | H27: Ведущий специалист | I27: 16 | J27: 1 | K27: 176000 | L27: 44727 | N27: =SUMIFS(salary_bands[salary_min],salary_bands[prof_group],G27,salary_bands[grade],I27) -> 164000 | O27: =SUMIFS(salary_bands[salary_mid],salary_bands[prof_group],G27,salary_bands[grade],I27) -> 193000 | P27: =SUMIFS(salary_bands[salary_max],salary_bands[prof_group],G27,salary_bands[grade],I27) -> 222000 | Q27: {=_xlfn.IFS(S27<N27,"ниже минимума",S27<=O27,"ниже середины",S27<=P27,"выше середины",S27>P27,"выше максимума")} -> ниже середины | R27: =IF(S27<N27,N27-S27,0) -> 0 | S27: =K27/J27 -> 176000 | T27: =IF(S27<O27,O27-S27,0) -> 17000 | U27: =IF(R27>0, R27*J27, 0) -> 0 | V27: =IF(AND(R27=0, T27>3000), T27*J27, 0) -> 17000 | W27: =U27+V27 -> 17000
A28: 1026 | B28: 45809 | C28: Денис Васильев | D28: Технологический блок | E28: аналитика данных | G28: Аналитика данных | H28: Руководитель группы | I28: 17 | J28: 1 | K28: 178000 | L28: 45342 | N28: =SUMIFS(salary_bands[salary_min],salary_bands[prof_group],G28,salary_bands[grade],I28) -> 172000 | O28: =SUMIFS(salary_bands[salary_mid],salary_bands[prof_group],G28,salary_bands[grade],I28) -> 202000 | P28: =SUMIFS(salary_bands[salary_max],salary_bands[prof_group],G28,salary_bands[grade],I28) -> 232000 | Q28: {=_xlfn.IFS(S28<N28,"ниже минимума",S28<=O28,"ниже середины",S28<=P28,"выше середины",S28>P28,"выше максимума")} -> ниже середины | R28: =IF(S28<N28,N28-S28,0) -> 0 | S28: =K28/J28 -> 178000 | T28: =IF(S28<O28,O28-S28,0) -> 24000 | U28: =IF(R28>0, R28*J28, 0) -> 0 | V28: =IF(AND(R28=0, T28>3000), T28*J28, 0) -> 24000 | W28: =U28+V28 -> 24000
A29: 1027 | B29: 45809 | C29: Елена Иванова | D29: Технологический блок | E29: аналитика данных | G29: Аналитика данных | H29: Руководитель группы | I29: 17 | J29: 1 | K29: 216000 | L29: 45342 | N29: =SUMIFS(salary_bands[salary_min],salary_bands[prof_group],G29,salary_bands[grade],I29) -> 172000 | O29: =SUMIFS(salary_bands[salary_mid],salary_bands[prof_group],G29,salary_bands[grade],I29) -> 202000 | P29: =SUMIFS(salary_bands[salary_max],salary_bands[prof_group],G29,salary_bands[grade],I29) -> 232000 | Q29: {=_xlfn.IFS(S29<N29,"ниже минимума",S29<=O29,"ниже середины",S29<=P29,"выше середины",S29>P29,"выше максимума")} -> выше середины | R29: =IF(S29<N29,N29-S29,0) -> 0 | S29: =K29/J29 -> 216000 | T29: =IF(S29<O29,O29-S29,0) -> 0 | U29: =IF(R29>0, R29*J29, 0) -> 0 | V29: =IF(AND(R29=0, T29>3000), T29*J29, 0) -> 0 | W29: =U29+V29 -> 0
... A90: 1088 | B90: 45809 | C90: Кирилл Морозов | D90: Операционный блок | E90: HR | G90: HR | H90: Ведущий специалист | I90: 16 | J90: 0.5 | K90: 75000 | L90: 45170 | N90: =SUMIFS(salary_bands[salary_min],salary_bands[prof_group],G90,salary_bands[grade],I90) -> 128000 | O90: =SUMIFS(salary_bands[salary_mid],salary_bands[prof_group],G90,salary_bands[grade],I90) -> 151000 | P90: =SUMIFS(salary_bands[salary_max],salary_bands[prof_group],G90,salary_bands[grade],I90) -> 174000 | Q90: {=_xlfn.IFS(S90<N90,"ниже минимума",S90<=O90,"ниже середины",S90<=P90,"выше середины",S90>P90,"выше максимума")} -> ниже середины | R90: =IF(S90<N90,N90-S90,0) -> 0 | S90: =K90/J90 -> 150000 | T90: =IF(S90<O90,O90-S90,0) -> 1000 | U90: =IF(R90>0, R90*J90, 0) -> 0 | V90: =IF(AND(R90=0, T90>3000), T90*J90, 0) -> 0 | W90: =U90+V90 -> 0
A91: 1089 | B91: 45809 | C91: Дарья Кузнецова | D91: Операционный блок | E91: Поддержка | G91: Поддержка | H91: Стажёр | I91: 12 | J91: 1 | K91: 110000 | L91: 44727 | N91: =SUMIFS(salary_bands[salary_min],salary_bands[prof_group],G91,salary_bands[grade],I91) -> 0 | O91: =SUMIFS(salary_bands[salary_mid],salary_bands[prof_group],G91,salary_bands[grade],I91) -> 0 | P91: =SUMIFS(salary_bands[salary_max],salary_bands[prof_group],G91,salary_bands[grade],I91) -> 0 | Q91: нет вилки (grade 12) | R91: =IF(S91<N91,N91-S91,0) -> 0 | S91: =K91/J91 -> 110000 | T91: =IF(S91<O91,O91-S91,0) -> 0 | U91: =IF(R91>0, R91*J91, 0) -> 0 | V91: =IF(AND(R91=0, T91>3000), T91*J91, 0) -> 0 | W91: =U91+V91 -> 0
A92: 1090 | B92: 45809 | C92: Фёдор Голубев | D92: Операционный блок | E92: Поддержка | G92: Поддержка | H92: Стажёр | I92: 12 | J92: 1 | K92: 117000 | L92: 45601 | N92: =SUMIFS(salary_bands[salary_min],salary_bands[prof_group],G92,salary_bands[grade],I92) -> 0 | O92: =SUMIFS(salary_bands[salary_mid],salary_bands[prof_group],G92,salary_bands[grade],I92) -> 0 | P92: =SUMIFS(salary_bands[salary_max],salary_bands[prof_group],G92,salary_bands[grade],I92) -> 0 | Q92: нет вилки (grade 12) | R92: =IF(S92<N92,N92-S92,0) -> 0 | S92: =K92/J92 -> 117000 | T92: =IF(S92<O92,O92-S92,0) -> 0 | U92: =IF(R92>0, R92*J92, 0) -> 0 | V92: =IF(AND(R92=0, T92>3000), T92*J92, 0) -> 0 | W92: =U92+V92 -> 0
A93: 1091 | B93: 45809 | C93: Ирина Волкова | D93: Операционный блок | E93: Поддержка | G93: Поддержка | H93: Стажёр | I93: 12 | J93: 1 | K93: 100000 | L93: 45170 | N93: =SUMIFS(salary_bands[salary_min],salary_bands[prof_group],G93,salary_bands[grade],I93) -> 0 | O93: =SUMIFS(salary_bands[salary_mid],salary_bands[prof_group],G93,salary_bands[grade],I93) -> 0 | P93: =SUMIFS(salary_bands[salary_max],salary_bands[prof_group],G93,salary_bands[grade],I93) -> 0 | Q93: нет вилки (grade 12) | R93: =IF(S93<N93,N93-S93,0) -> 0 | S93: =K93/J93 -> 100000 | T93: =IF(S93<O93,O93-S93,0) -> 0 | U93: =IF(R93>0, R93*J93, 0) -> 0 | V93: =IF(AND(R93=0, T93>3000), T93*J93, 0) -> 0 | W93: =U93+V93 -> 0
A94: 1092 | B94: 45809 | C94: Артём Васильев | D94: Операционный блок | E94: Поддержка | G94: Поддержка | H94: Младший специалист | I94: 13 | J94: 1 | K94: 123000 | L94: 45601 | N94: =SUMIFS(salary_bands[salary_min],salary_bands[prof_group],G94,salary_bands[grade],I94) -> 98000 | O94: =SUMIFS(salary_bands[salary_mid],salary_bands[prof_group],G94,salary_bands[grade],I94) -> 115000 | P94: =SUMIFS(salary_bands[salary_max],salary_bands[prof_group],G94,salary_bands[grade],I94) -> 132000 | Q94: {=_xlfn.IFS(S94<N94,"ниже минимума",S94<=O94,"ниже середины",S94<=P94,"выше середины",S94>P94,"выше максимума")} -> выше середины | R94: =IF(S94<N94,N94-S94,0) -> 0 | S94: =K94/J94 -> 123000 | T94: =IF(S94<O94,O94-S94,0) -> 0 | U94: =IF(R94>0, R94*J94, 0) -> 0 | V94: =IF(AND(R94=0, T94>3000), T94*J94, 0) -> 0 | W94: =U94+V94 -> 0
A95: 1093 | B95: 45809 | C95: Дарья Соловьёва | D95: Операционный блок | E95: Поддержка | G95: Поддержка | H95: Младший специалист | I95: 13 | J95: 1 | K95: 106000 | L95: 44256 | N95: =SUMIFS(salary_bands[salary_min],salary_bands[prof_group],G95,salary_bands[grade],I95) -> 98000 | O95: =SUMIFS(salary_bands[salary_mid],salary_bands[prof_group],G95,salary_bands[grade],I95) -> 115000 | P95: =SUMIFS(salary_bands[salary_max],salary_bands[prof_group],G95,salary_bands[grade],I95) -> 132000 | Q95: {=_xlfn.IFS(S95<N95,"ниже минимума",S95<=O95,"ниже середины",S95<=P95,"выше середины",S95>P95,"выше максимума")} -> ниже середины | R95: =IF(S95<N95,N95-S95,0) -> 0 | S95: =K95/J95 -> 106000 | T95: =IF(S95<O95,O95-S95,0) -> 9000 | U95: =IF(R95>0, R95*J95, 0) -> 0 | V95: =IF(AND(R95=0, T95>3000), T95*J95, 0) -> 9000 | W95: =U95+V95 -> 9000
A96: 1094 | B96: 45809 | C96: Роман Волков | D96: Операционный блок | E96: Поддержка | G96: Поддержка | H96: Младший специалист | I96: 13 | J96: 1 | K96: 123000 | L96: 44256 | N96: =SUMIFS(salary_bands[salary_min],salary_bands[prof_group],G96,salary_bands[grade],I96) -> 98000 | O96: =SUMIFS(salary_bands[salary_mid],salary_bands[prof_group],G96,salary_bands[grade],I96) -> 115000 | P96: =SUMIFS(salary_bands[salary_max],salary_bands[prof_group],G96,salary_bands[grade],I96) -> 132000 | Q96: {=_xlfn.IFS(S96<N96,"ниже минимума",S96<=O96,"ниже середины",S96<=P96,"выше середины",S96>P96,"выше максимума")} -> выше середины | R96: =IF(S96<N96,N96-S96,0) -> 0 | S96: =K96/J96 -> 123000 | T96: =IF(S96<O96,O96-S96,0) -> 0 | U96: =IF(R96>0, R96*J96, 0) -> 0 | V96: =IF(AND(R96=0, T96>3000), T96*J96, 0) -> 0 | W96: =U96+V96 -> 0
A97: 1095 | B97: 45809 | C97: Полина Смирнова | D97: Операционный блок | E97: Поддержка | G97: Поддержка | H97: Младший специалист | I97: 13 | J97: 1 | K97: 110000 | L97: 44520 | N97: =SUMIFS(salary_bands[salary_min],salary_bands[prof_group],G97,salary_bands[grade],I97) -> 98000 | O97: =SUMIFS(salary_bands[salary_mid],salary_bands[prof_group],G97,salary_bands[grade],I97) -> 115000 | P97: =SUMIFS(salary_bands[salary_max],salary_bands[prof_group],G97,salary_bands[grade],I97) -> 132000 | Q97: {=_xlfn.IFS(S97<N97,"ниже минимума",S97<=O97,"ниже середины",S97<=P97,"выше середины",S97>P97,"выше максимума")} -> ниже середины | R97: =IF(S97<N97,N97-S97,0) -> 0 | S97: =K97/J97 -> 110000 | T97: =IF(S97<O97,O97-S97,0) -> 5000 | U97: =IF(R97>0, R97*J97, 0) -> 0 | V97: =IF(AND(R97=0, T97>3000), T97*J97, 0) -> 5000 | W97: =U97+V97 -> 5000
A98: 1096 | B98: 45809 | C98: Сергей Голубев | D98: Операционный блок | E98: Поддержка | G98: Поддержка | H98: Специалист | I98: 14 | J98: 0.8 | K98: 92000 | L98: 44256 | N98: =SUMIFS(salary_bands[salary_min],salary_bands[prof_group],G98,salary_bands[grade],I98) -> 104000 | O98: =SUMIFS(salary_bands[salary_mid],salary_bands[prof_group],G98,salary_bands[grade],I98) -> 122000 | P98: =SUMIFS(salary_bands[salary_max],salary_bands[prof_group],G98,salary_bands[grade],I98) -> 140000 | Q98: {=_xlfn.IFS(S98<N98,"ниже минимума",S98<=O98,"ниже середины",S98<=P98,"выше середины",S98>P98,"выше максимума")} -> ниже середины | R98: =IF(S98<N98,N98-S98,0) -> 0 | S98: =K98/J98 -> 115000 | T98: =IF(S98<O98,O98-S98,0) -> 7000 | U98: =IF(R98>0, R98*J98, 0) -> 0 | V98: =IF(AND(R98=0, T98>3000), T98*J98, 0) -> 5600 | W98: =U98+V98 -> 5600
A99: 1097 | B99: 45809 | C99: Маргарита Соловьёва | D99: Операционный блок | E99: Поддержка | G99: Поддержка | H99: Специалист | I99: 14 | J99: 1 | K99: 121000 | L99: 44520 | N99: =SUMIFS(salary_bands[salary_min],salary_bands[prof_group],G99,salary_bands[grade],I99) -> 104000 | O99: =SUMIFS(salary_bands[salary_mid],salary_bands[prof_group],G99,salary_bands[grade],I99) -> 122000 | P99: =SUMIFS(salary_bands[salary_max],salary_bands[prof_group],G99,salary_bands[grade],I99) -> 140000 | Q99: {=_xlfn.IFS(S99<N99,"ниже минимума",S99<=O99,"ниже середины",S99<=P99,"выше середины",S99>P99,"выше максимума")} -> ниже середины | R99: =IF(S99<N99,N99-S99,0) -> 0 | S99: =K99/J99 -> 121000 | T99: =IF(S99<O99,O99-S99,0) -> 1000 | U99: =IF(R99>0, R99*J99, 0) -> 0 | V99: =IF(AND(R99=0, T99>3000), T99*J99, 0) -> 0 | W99: =U99+V99 -> 0
A100: 1098 | B100: 45809 | C100: Дмитрий Кузнецов | D100: Операционный блок | E100: Поддержка | G100: Поддержка | H100: Специалист | I100: 14 | J100: 1 | K100: 135000 | L100: 45342 | N100: =SUMIFS(salary_bands[salary_min],salary_bands[prof_group],G100,salary_bands[grade],I100) -> 104000 | O100: =SUMIFS(salary_bands[salary_mid],salary_bands[prof_group],G100,salary_bands[grade],I100) -> 122000 | P100: =SUMIFS(salary_bands[salary_max],salary_bands[prof_group],G100,salary_bands[grade],I100) -> 140000 | Q100: {=_xlfn.IFS(S100<N100,"ниже минимума",S100<=O100,"ниже середины",S100<=P100,"выше середины",S100>P100,"выше максимума")} -> выше середины | R100: =IF(S100<N100,N100-S100,0) -> 0 | S100: =K100/J100 -> 135000 | T100: =IF(S100<O100,O100-S100,0) -> 0 | U100: =IF(R100>0, R100*J100, 0) -> 0 | V100: =IF(AND(R100=0, T100>3000), T100*J100, 0) -> 0 | W100: =U100+V100 -> 0
A101: 1099 | B101: 45809 | C101: Наталья Соколова | D101: Операционный блок | E101: Поддержка | G101: Поддержка | H101: Старший специалист | I101: 15 | J101: 1 | K101: 135000 | L101: 44936 | N101: =SUMIFS(salary_bands[salary_min],salary_bands[prof_group],G101,salary_bands[grade],I101) -> 109000 | O101: =SUMIFS(salary_bands[salary_mid],salary_bands[prof_group],G101,salary_bands[grade],I101) -> 128000 | P101: =SUMIFS(salary_bands[salary_max],salary_bands[prof_group],G101,salary_bands[grade],I101) -> 147000 | Q101: {=_xlfn.IFS(S101<N101,"ниже минимума",S101<=O101,"ниже середины",S101<=P101,"выше середины",S101>P101,"выше максимума")} -> выше середины | R101: =IF(S101<N101,N101-S101,0) -> 0 | S101: =K101/J101 -> 135000 | T101: =IF(S101<O101,O101-S101,0) -> 0 | U101: =IF(R101>0, R101*J101, 0) -> 0 | V101: =IF(AND(R101=0, T101>3000), T101*J101, 0) -> 0 | W101: =U101+V101 -> 0
A102: 1100 | B102: 45809 | C102: Денис Новиков | D102: Операционный блок | E102: Поддержка | G102: Поддержка | H102: Старший специалист | I102: 15 | J102: 0.3 | K102: 39000 | L102: 45342 | N102: =SUMIFS(salary_bands[salary_min],salary_bands[prof_group],G102,salary_bands[grade],I102) -> 109000 | O102: =SUMIFS(salary_bands[salary_mid],salary_bands[prof_group],G102,salary_bands[grade],I102) -> 128000 | P102: =SUMIFS(salary_bands[salary_max],salary_bands[prof_group],G102,salary_bands[grade],I102) -> 147000 | Q102: {=_xlfn.IFS(S102<N102,"ниже минимума",S102<=O102,"ниже середины",S102<=P102,"выше середины",S102>P102,"выше максимума")} -> выше середины | R102: =IF(S102<N102,N102-S102,0) -> 0 | S102: =K102/J102 -> 130000 | T102: =IF(S102<O102,O102-S102,0) -> 0 | U102: =IF(R102>0, R102*J102, 0) -> 0 | V102: =IF(AND(R102=0, T102>3000), T102*J102, 0) -> 0 | W102: =U102+V102 -> 0
A103: 1101 | B103: 45809 | C103: Вероника Волкова | D103: Операционный блок | E103: Поддержка | G103: Поддержка | H103: Старший специалист | I103: 15 | J103: 0.6 | K103: 85200 | L103: 43845 | N103: =SUMIFS(salary_bands[salary_min],salary_bands[prof_group],G103,salary_bands[grade],I103) -> 109000 | O103: =SUMIFS(salary_bands[salary_mid],salary_bands[prof_group],G103,salary_bands[grade],I103) -> 128000 | P103: =SUMIFS(salary_bands[salary_max],salary_bands[prof_group],G103,salary_bands[grade],I103) -> 147000 | Q103: {=_xlfn.IFS(S103<N103,"ниже минимума",S103<=O103,"ниже середины",S103<=P103,"выше середины",S103>P103,"выше максимума")} -> выше середины | R103: =IF(S103<N103,N103-S103,0) -> 0 | S103: =K103/J103 -> 142000 | T103: =IF(S103<O103,O103-S103,0) -> 0 | U103: =IF(R103>0, R103*J103, 0) -> 0 | V103: =IF(AND(R103=0, T103>3000), T103*J103, 0) -> 0 | W103: =U103+V103 -> 0
...

Sheet Бюджет
A1: Отдел | B1: Лимит | C1: Потребность | D1: В рамках лимита | E1: Остаток
A2: Разработка | B2: 130000 | C2: =SUMIFS(Анализ!W:W, Анализ!G:G, A2) -> 107700 | D2: =MIN(C2,B2) -> 107700 | E2: =B2-D2 -> 22300
A3: Аналитика данных | B3: 210000 | C3: =SUMIFS(Анализ!W:W, Анализ!G:G, A3) -> 122900 | D3: =MIN(C3,B3) -> 122900 | E3: =B3-D3 -> 87100
A4: Инфраструктура | B4: 100000 | C4: =SUMIFS(Анализ!W:W, Анализ!G:G, A4) -> 133400 | D4: =MIN(C4,B4) -> 100000 | E4: =B4-D4 -> 0
A5: Бюджетирование | B5: 120000 | C5: =SUMIFS(Анализ!W:W, Анализ!G:G, A5) -> 61200 | D5: 61200 | E5: =B5-D5 -> 58800
A6: Компенсации и льготы | B6: 220000 | C6: =SUMIFS(Анализ!W:W, Анализ!G:G, A6) -> 117600 | D6: =MIN(C6,B6) -> 117600 | E6: =B6-D6 -> 102400
A7: HR | B7: 80000 | C7: =SUMIFS(Анализ!W:W, Анализ!G:G, A7) -> 47750 | D7: =MIN(C7,B7) -> 47750 | E7: =B7-D7 -> 32250
A8: Поддержка | B8: 100000 | C8: =SUMIFS(Анализ!W:W, Анализ!G:G, A8) -> 42600 | D8: =MIN(C8,B8) -> 42600 | E8: =B8-D8 -> 57400
A9: Итого | B9: =SUM(B2:B8) -> 960000 | C9: =SUM(C2:C8) -> 633150 | D9: =SUM(D2:D8) -> 599750 | E9: =SUM(E2:E8) -> 360250
A11: Инфраструктура — детализация (лимит 100 000)
A12: ФИО | B12: Приоритет | C12: Нужно | D12: Выделено | E12: Статус
A13: Матвей Крылов | B13: ниже минимума | C13: 27000 | D13: 27000 | E13: Поднят
A14: Алексей Павлов | B14: ниже середины | C14: 24000 | D14: 24000 | E14: Поднят
A15: Мария Соловьёва | B15: ниже середины | C15: 22000 | D15: 22000 | E15: Поднят
A16: Светлана Соколова | B16: ниже середины | C16: 16000 | D16: 16000 | E16: Поднят
A17: Григорий Павлов | B17: ниже середины | C17: 12000 | D17: 11000 | E17: Частично
A18: Фёдор Голубев | B18: ниже середины | C18: 8000 | D18: 0 | E18: Перенос
A19: Григорий Волков | B19: ниже середины | C19: 7200 | D19: 0 | E19: Перенос
A20: Вероника Морозова | B20: ниже середины | C20: 7200 | D20: 0 | E20: Перенос
A21: Елена Соколова | B21: ниже середины | C21: 7000 | D21: 0 | E21: Перенос
A22: Алина Морозова | B22: ниже середины | C22: 3000 | D22: 0 | E22: Перенос
D23: =SUM(D13:D22) -> 100000
A25: Примечание: 3 стажёра Поддержки (grade 12) исключены из анализа - в salary_bands отсутствует вилка для этого грейда.

Sheet График
A1: Статус | B1: Количество
A2: Ниже минимума | B2: 9
A3: Ниже середины | B3: 47
A4: Выше середины | B4: 54
A5: Выше максимума | B5: 4
A6: Нет вилки | B6: 3
