Workbook

Sheet Анализ_отделы
A3: Отдел | B3: Выручка | C3: Количество сделок | D3: Средний чек
A4: Отдел А | B4: 2459118 | C4: 25 | D4: =B4/C4 -> 98364.72
A5: Отдел Б | B5: 4040505 | C5: 27 | D5: =B5/C5 -> 149648.33
A6: Отдел В | B6: 3970892 | C6: 27 | D6: =B6/C6 -> 147070.07
A7: Отдел Г | B7: 3252915 | C7: 19 | D7: =B7/C7 -> 171206.05
A8: Общий итог | B8: 13723430 | C8: 98 | D8: =B8/C8 -> 140035

Sheet Анализ_товары
A3: Товар | B3: Выручка | C3: Доля % | D3: Категория
A4: Клавиатура | B4: 209211 | C4: =B4/B$11 -> 0.015244804 | D4: =_xlfn.XLOOKUP(A4,Данные!G2:G99,Данные!H2:H99,"") -> Аксессуары
A5: Монитор | B5: 1824543 | C5: =B5/B$11 -> 0.13295095 | D5: =_xlfn.XLOOKUP(A5,Данные!G3:G100,Данные!H3:H100,"") -> Техника
A6: Мышь | B6: 54858 | C6: =B6/B$11 -> 0.0039973972 | D6: =_xlfn.XLOOKUP(A6,Данные!G4:G101,Данные!H4:H101,"") -> Аксессуары
A7: Наушники | B7: 375723 | C7: =B7/B$11 -> 0.027378214 | D7: =_xlfn.XLOOKUP(A7,Данные!G5:G102,Данные!H5:H102,"") -> Аксессуары
A8: Ноутбук | B8: 5718275 | C8: =B8/B$11 -> 0.41667972 | D8: =_xlfn.XLOOKUP(A8,Данные!G6:G103,Данные!H6:H103,"") -> Техника
A9: Планшет | B9: 1793105 | C9: =B9/B$11 -> 0.13066012 | D9: =_xlfn.XLOOKUP(A9,Данные!G7:G104,Данные!H7:H104,"") -> Техника
A10: Телефон | B10: 3747715 | C10: =B10/B$11 -> 0.2730888 | D10: =_xlfn.XLOOKUP(A10,Данные!G8:G105,Данные!H8:H105,"") -> Техника
A11: Общий итог | B11: 13723430

Sheet Анализ_динамика
A3: Месяц | B3: Выручка
A4: янв | B4: 1006796
A5: февр | B5: 1230579
A6: март | B6: 1316880
A7: апр | B7: 163355
A8: май | B8: 1009776
A9: июнь | B9: 1467519
A10: июль | B10: 748505
A11: авг | B11: 2718567
A12: сент | B12: 1478769
A13: окт | B13: 1011544
A14: нояб | B14: 901740
A15: дек | B15: 669400
A16: Общий итог | B16: 13723430

Sheet Рейтинг_менеджеров
A1: ФИО | B1: Отдел | C1: План (руб) | D1: Факт (руб) | E1: Выполнение % | F1: Кол-во сделок | G1: Средний чек | H1: Место | I1: Статус
A2: {=_xlfn.UNIQUE(Данные!A2:A99)} -> Иванов И.И. | B2: =_xlfn.XLOOKUP(A2,Данные!A:A,Данные!B:B,"") -> Отдел А | C2: =_xlfn.XLOOKUP(A2,Данные!A:A,Данные!C:C,0) -> 520000 | D2: =SUMIFS(Данные!K:K,Данные!A:A,A2) -> 549452 | E2: =IFERROR(D2/C2,0) -> 1.0566385 | F2: =COUNTIF(Данные!A:A,A2) -> 6 | G2: =IFERROR(D2/F2,0) -> 91575.333 | H2: =RANK(D2,D$2:D$16,0) -> 10 | I2: =IF(E2>=1,"Выполнен","Не выполнен") -> Выполнен
A3: Морозова Е.Н. | B3: =_xlfn.XLOOKUP(A3,Данные!A:A,Данные!B:B,"") -> Отдел Б | C3: =_xlfn.XLOOKUP(A3,Данные!A:A,Данные!C:C,0) -> 540000 | D3: =SUMIFS(Данные!K:K,Данные!A:A,A3) -> 1060609 | E3: =IFERROR(D3/C3,0) -> 1.9640907 | F3: =COUNTIF(Данные!A:A,A3) -> 6 | G3: =IFERROR(D3/F3,0) -> 176768.17 | H3: =RANK(D3,D$2:D$16,0) -> 8 | I3: =IF(E3>=1,"Выполнен","Не выполнен") -> Выполнен
A4: Попова Н.А. | B4: =_xlfn.XLOOKUP(A4,Данные!A:A,Данные!B:B,"") -> Отдел В | C4: =_xlfn.XLOOKUP(A4,Данные!A:A,Данные!C:C,0) -> 370000 | D4: =SUMIFS(Данные!K:K,Данные!A:A,A4) -> 817254 | E4: =IFERROR(D4/C4,0) -> 2.2087946 | F4: =COUNTIF(Данные!A:A,A4) -> 9 | G4: =IFERROR(D4/F4,0) -> 90806 | H4: =RANK(D4,D$2:D$16,0) -> 9 | I4: =IF(E4>=1,"Выполнен","Не выполнен") -> Выполнен
A5: Новиков А.В. | B5: =_xlfn.XLOOKUP(A5,Данные!A:A,Данные!B:B,"") -> Отдел А | C5: =_xlfn.XLOOKUP(A5,Данные!A:A,Данные!C:C,0) -> 610000 | D5: =SUMIFS(Данные!K:K,Данные!A:A,A5) -> 370624 | E5: =IFERROR(D5/C5,0) -> 0.60758033 | F5: =COUNTIF(Данные!A:A,A5) -> 7 | G5: =IFERROR(D5/F5,0) -> 52946.286 | H5: =RANK(D5,D$2:D$16,0) -> 13 | I5: =IF(E5>=1,"Выполнен","Не выполнен") -> Не выполнен
A6: Козлова М.Д. | B6: =_xlfn.XLOOKUP(A6,Данные!A:A,Данные!B:B,"") -> Отдел Г | C6: =_xlfn.XLOOKUP(A6,Данные!A:A,Данные!C:C,0) -> 390000 | D6: =SUMIFS(Данные!K:K,Данные!A:A,A6) -> 263338 | E6: =IFERROR(D6/C6,0) -> 0.67522564 | F6: =COUNTIF(Данные!A:A,A6) -> 4 | G6: =IFERROR(D6/F6,0) -> 65834.5 | H6: =RANK(D6,D$2:D$16,0) -> 14 | I6: =IF(E6>=1,"Выполнен","Не выполнен") -> Не выполнен
A7: Сидоров П.А. | B7: =_xlfn.XLOOKUP(A7,Данные!A:A,Данные!B:B,"") -> Отдел А | C7: =_xlfn.XLOOKUP(A7,Данные!A:A,Данные!C:C,0) -> 430000 | D7: =SUMIFS(Данные!K:K,Данные!A:A,A7) -> 1135842 | E7: =IFERROR(D7/C7,0) -> 2.641493 | F7: =COUNTIF(Данные!A:A,A7) -> 8 | G7: =IFERROR(D7/F7,0) -> 141980.25 | H7: =RANK(D7,D$2:D$16,0) -> 7 | I7: =IF(E7>=1,"Выполнен","Не выполнен") -> Выполнен
A8: Соколов А.П. | B8: =_xlfn.XLOOKUP(A8,Данные!A:A,Данные!B:B,"") -> Отдел Б | C8: =_xlfn.XLOOKUP(A8,Данные!A:A,Данные!C:C,0) -> 630000 | D8: =SUMIFS(Данные!K:K,Данные!A:A,A8) -> 1652175 | E8: =IFERROR(D8/C8,0) -> 2.6225 | F8: =COUNTIF(Данные!A:A,A8) -> 8 | G8: =IFERROR(D8/F8,0) -> 206521.88 | H8: =RANK(D8,D$2:D$16,0) -> 1 | I8: =IF(E8>=1,"Выполнен","Не выполнен") -> Выполнен
A9: Григорьев С.П. | B9: =_xlfn.XLOOKUP(A9,Данные!A:A,Данные!B:B,"") -> Отдел В | C9: =_xlfn.XLOOKUP(A9,Данные!A:A,Данные!C:C,0) -> 510000 | D9: =SUMIFS(Данные!K:K,Данные!A:A,A9) -> 1361151 | E9: =IFERROR(D9/C9,0) -> 2.6689235 | F9: =COUNTIF(Данные!A:A,A9) -> 7 | G9: =IFERROR(D9/F9,0) -> 194450.14 | H9: =RANK(D9,D$2:D$16,0) -> 5 | I9: =IF(E9>=1,"Выполнен","Не выполнен") -> Выполнен
A10: Петрова А.С. | B10: =_xlfn.XLOOKUP(A10,Данные!A:A,Данные!B:B,"") -> Отдел Б | C10: =_xlfn.XLOOKUP(A10,Данные!A:A,Данные!C:C,0) -> 680000 | D10: =SUMIFS(Данные!K:K,Данные!A:A,A10) -> 158552 | E10: =IFERROR(D10/C10,0) -> 0.23316471 | F10: =COUNTIF(Данные!A:A,A10) -> 4 | G10: =IFERROR(D10/F10,0) -> 39638 | H10: =RANK(D10,D$2:D$16,0) -> 15 | I10: =IF(E10>=1,"Выполнен","Не выполнен") -> Не выполнен
A11: Федорова И.М. | B11: =_xlfn.XLOOKUP(A11,Данные!A:A,Данные!B:B,"") -> Отдел Г | C11: =_xlfn.XLOOKUP(A11,Данные!A:A,Данные!C:C,0) -> 420000 | D11: =SUMIFS(Данные!K:K,Данные!A:A,A11) -> 1610247 | E11: =IFERROR(D11/C11,0) -> 3.8339214 | F11: =COUNTIF(Данные!A:A,A11) -> 8 | G11: =IFERROR(D11/F11,0) -> 201280.88 | H11: =RANK(D11,D$2:D$16,0) -> 2 | I11: =IF(E11>=1,"Выполнен","Не выполнен") -> Выполнен
A12: Орлов В.С. | B12: =_xlfn.XLOOKUP(A12,Данные!A:A,Данные!B:B,"") -> Отдел Б | C12: =_xlfn.XLOOKUP(A12,Данные!A:A,Данные!C:C,0) -> 580000 | D12: =SUMIFS(Данные!K:K,Данные!A:A,A12) -> 1169169 | E12: =IFERROR(D12/C12,0) -> 2.0158086 | F12: =COUNTIF(Данные!A:A,A12) -> 9 | G12: =IFERROR(D12/F12,0) -> 129907.67 | H12: =RANK(D12,D$2:D$16,0) -> 6 | I12: =IF(E12>=1,"Выполнен","Не выполнен") -> Выполнен
A13: Волков Д.А. | B13: =_xlfn.XLOOKUP(A13,Данные!A:A,Данные!B:B,"") -> Отдел В | C13: =_xlfn.XLOOKUP(A13,Данные!A:A,Данные!C:C,0) -> 470000 | D13: =SUMIFS(Данные!K:K,Данные!A:A,A13) -> 1366957 | E13: =IFERROR(D13/C13,0) -> 2.9084191 | F13: =COUNTIF(Данные!A:A,A13) -> 4 | G13: =IFERROR(D13/F13,0) -> 341739.25 | H13: =RANK(D13,D$2:D$16,0) -> 4 | I13: =IF(E13>=1,"Выполнен","Не выполнен") -> Выполнен
A14: Лебедева О.И. | B14: =_xlfn.XLOOKUP(A14,Данные!A:A,Данные!B:B,"") -> Отдел Г | C14: =_xlfn.XLOOKUP(A14,Данные!A:A,Данные!C:C,0) -> 410000 | D14: =SUMIFS(Данные!K:K,Данные!A:A,A14) -> 1379330 | E14: =IFERROR(D14/C14,0) -> 3.3642195 | F14: =COUNTIF(Данные!A:A,A14) -> 7 | G14: =IFERROR(D14/F14,0) -> 197047.14 | H14: =RANK(D14,D$2:D$16,0) -> 3 | I14: =IF(E14>=1,"Выполнен","Не выполнен") -> Выполнен
... A16: Зайцев М.Ю. | B16: =_xlfn.XLOOKUP(A16,Данные!A:A,Данные!B:B,"") -> Отдел А | C16: =_xlfn.XLOOKUP(A16,Данные!A:A,Данные!C:C,0) -> 490000 | D16: =SUMIFS(Данные!K:K,Данные!A:A,A16) -> 403200 | E16: =IFERROR(D16/C16,0) -> 0.82285714 | F16: =COUNTIF(Данные!A:A,A16) -> 4 | G16: =IFERROR(D16/F16,0) -> 100800 | H16: =RANK(D16,D$2:D$16,0) -> 12 | I16: =IF(E16>=1,"Выполнен","Не выполнен") -> Не выполнен

Sheet Справка
A1: Финансово-аналитическая справка - Продажи сети отделений 2024 г.
A2: Период: январь – декабрь 2024 г. | Источник: Данные_продажи.xlsx | Выборка: 98 сделок, 15 менеджеров, 4 отдела
A4: Ключевые показатели
A5: Общая выручка | B5: =Анализ_отделы!B8 -> 13723430
A6: Количество сделок | B6: =98 -> 98
A7: Средний чек | B7: =B5/B6 -> 140035
A8: Среднее выполнение плана | B8: =AVERAGE(Рейтинг_менеджеров!E2:E16)*100 -> 190.46173
A10: Структура продаж
A11: Отдел | B11: Выручка | C11: Доля % | D11: Количество сделок | E11: Средний чек
A12: =Анализ_отделы!A4 -> Отдел А | B12: =Анализ_отделы!B4 -> 2459118 | C12: =B12/13723430 -> 0.17919121 | D12: =Анализ_отделы!C4 -> 25 | E12: =Анализ_отделы!D4 -> 98364.72
A13: =Анализ_отделы!A5 -> Отдел Б | B13: =Анализ_отделы!B5 -> 4040505 | C13: =B13/13723430 -> 0.29442384 | D13: =Анализ_отделы!C5 -> 27 | E13: =Анализ_отделы!D5 -> 149648.33
A14: =Анализ_отделы!A6 -> Отдел В | B14: =Анализ_отделы!B6 -> 3970892 | C14: =B14/13723430 -> 0.28935128 | D14: =Анализ_отделы!C6 -> 27 | E14: =Анализ_отделы!D6 -> 147070.07
A15: =Анализ_отделы!A7 -> Отдел Г | B15: =Анализ_отделы!B7 -> 3252915 | C15: =B15/13723430 -> 0.23703367 | D15: =Анализ_отделы!C7 -> 19 | E15: =Анализ_отделы!D7 -> 171206.05
A16: Итого | B16: =SUM(B12:B15) -> 13723430 | C16: 1 | D16: =SUM(D12:D15) -> 98 | E16: =AVERAGE(E12:E15) -> 141572.3
A18: Динамика продаж
A19: Месяц | B19: Выручка
A20: =Анализ_динамика!A4 -> янв | B20: =Анализ_динамика!B4 -> 1006796
A21: =Анализ_динамика!A5 -> февр | B21: =Анализ_динамика!B5 -> 1230579
A22: =Анализ_динамика!A6 -> март | B22: =Анализ_динамика!B6 -> 1316880
A23: =Анализ_динамика!A7 -> апр | B23: =Анализ_динамика!B7 -> 163355
A24: =Анализ_динамика!A8 -> май | B24: =Анализ_динамика!B8 -> 1009776
A25: =Анализ_динамика!A9 -> июнь | B25: =Анализ_динамика!B9 -> 1467519
A26: =Анализ_динамика!A10 -> июль | B26: =Анализ_динамика!B10 -> 748505
A27: =Анализ_динамика!A11 -> авг | B27: =Анализ_динамика!B11 -> 2718567
A28: =Анализ_динамика!A12 -> сент | B28: =Анализ_динамика!B12 -> 1478769
A29: =Анализ_динамика!A13 -> окт | B29: =Анализ_динамика!B13 -> 1011544
A30: =Анализ_динамика!A14 -> нояб | B30: =Анализ_динамика!B14 -> 901740
A31: =Анализ_динамика!A15 -> дек | B31: =Анализ_динамика!B15 -> 669400
A32: Итого | B32: =SUM(B20:B31) -> 13723430
A34: Кадровый срез
A35: ФИО | B35: Отдел | C35: Факт | D35: Выполнение % | E35: Место
A36: =Рейтинг_менеджеров!A8 -> Соколов А.П. | B36: =Рейтинг_менеджеров!B8 -> Отдел Б | C36: =Рейтинг_менеджеров!D8 -> 1652175 | D36: =Рейтинг_менеджеров!E8 -> 2.6225 | E36: =Рейтинг_менеджеров!H8 -> 1
A37: =Рейтинг_менеджеров!A10 -> Петрова А.С. | B37: =Рейтинг_менеджеров!B10 -> Отдел Б | C37: =Рейтинг_менеджеров!D10 -> 158552 | D37: =Рейтинг_менеджеров!E10 -> 0.23316471 | E37: =Рейтинг_менеджеров!H10 -> 15
A39: Выводы
A40: 1. Отдел Б формирует 29,4% совокупной выручки (4 040 505 руб.) при среднем чеке 149 648 руб. - максимальный вклад среди четырёх отделов.
A41: 2. Ноутбуки и телефоны обеспечивают 69% выручки - высокая товарная концентрация создаёт риск при перебоях поставок по этим позициям.
A42: 3. Апрель - провальный месяц: выручка 163 355 руб. против среднемесячной 1 143 619 руб. Требует отдельного анализа причин.
A43: 4. Разрыв между лидером (Соколов А.П., 262%) и аутсайдером (Петрова А.С., 23%) составляет 11,4x - свидетельствует о неравномерном распределении нагрузки или клиентской базы.
A45: Рекомендации
A46: 1. Развить ассортимент аксессуаров: их доля составляет лишь 4,6% выручки при наличии устойчивого спроса на технику. Кросс-продажи к ноутбукам и телефонам способны увеличить средний чек на 5–10%.
...

Sheet Данные
A1: ФИО менеджера | B1: Отдел | C1: План (руб) | D1: Дата | E1: Месяц | F1: Квартал | G1: Товар | H1: Категория | I1: Кол-во | J1: Цена (руб) | K1: Сумма (руб)
A2: Иванов И.И. | B2: Отдел А | C2: 520000 | D2: 45294 | E2: Январь | F2: Q1 | G2: Монитор | H2: Техника | I2: 4 | J2: 24497 | K2: 97988
A3: Морозова Е.Н. | B3: Отдел Б | C3: 540000 | D3: 45296 | E3: Январь | F3: Q1 | G3: Монитор | H3: Техника | I3: 6 | J3: 24785 | K3: 148710
A4: Попова Н.А. | B4: Отдел В | C4: 370000 | D4: 45296 | E4: Январь | F4: Q1 | G4: Клавиатура | H4: Аксессуары | I4: 3 | J4: 2965 | K4: 8895
A5: Новиков А.В. | B5: Отдел А | C5: 610000 | D5: 45298 | E5: Январь | F5: Q1 | G5: Наушники | H5: Аксессуары | I5: 4 | J5: 7438 | K5: 29752
A6: Морозова Е.Н. | B6: Отдел Б | C6: 540000 | D6: 45298 | E6: Январь | F6: Q1 | G6: Ноутбук | H6: Техника | I6: 8 | J6: 77062 | K6: 616496
A7: Новиков А.В. | B7: Отдел А | C7: 610000 | D7: 45307 | E7: Январь | F7: Q1 | G7: Наушники | H7: Аксессуары | I7: 5 | J7: 7667 | K7: 38335
A8: Козлова М.Д. | B8: Отдел Г | C8: 390000 | D8: 45315 | E8: Январь | F8: Q1 | G8: Мышь | H8: Аксессуары | I8: 8 | J8: 1294 | K8: 10352
A9: Сидоров П.А. | B9: Отдел А | C9: 430000 | D9: 45322 | E9: Январь | F9: Q1 | G9: Мышь | H9: Аксессуары | I9: 6 | J9: 1264 | K9: 7584
A10: Козлова М.Д. | B10: Отдел Г | C10: 390000 | D10: 45322 | E10: Январь | F10: Q1 | G10: Монитор | H10: Техника | I10: 2 | J10: 24342 | K10: 48684
A11: Новиков А.В. | B11: Отдел А | C11: 610000 | D11: 45328 | E11: Февраль | F11: Q1 | G11: Телефон | H11: Техника | I11: 4 | J11: 43599 | K11: 174396
A12: Соколов А.П. | B12: Отдел Б | C12: 630000 | D12: 45330 | E12: Февраль | F12: Q1 | G12: Ноутбук | H12: Техника | I12: 4 | J12: 71492 | K12: 285968
A13: Козлова М.Д. | B13: Отдел Г | C13: 390000 | D13: 45331 | E13: Февраль | F13: Q1 | G13: Монитор | H13: Техника | I13: 2 | J13: 25186 | K13: 50372
... A99: Соколов А.П. | B99: Отдел Б | C99: 630000 | D99: 45654 | E99: Декабрь | F99: Q4 | G99: Телефон | H99: Техника | I99: 7 | J99: 46171 | K99: 323197
